-07 03:23:13 UTC)" (scheduled at 2025-08-07 03:22:43.642564+00:00)
INFO:apscheduler.executors.default:Job "check_price_alerts (trigger: interval[0:00:30], next run at: 2025-08-07 03:23:13 UTC)" executed successfully
[2025-08-07 03:22:47 +0000] [11484] [ERROR] Socket error processing request.
Traceback (most recent call last):
  File "/home/runner/workspace/.pythonlibs/lib/python3.11/site-packages/gunicorn/workers/sync.py", line 134, in handle
    self.handle_request(listener, req, client, addr)
  File "/home/runner/workspace/.pythonlibs/lib/python3.11/site-packages/gunicorn/workers/sync.py", line 192, in handle_request
    util.reraise(*sys.exc_info())
  File "/home/runner/workspace/.pythonlibs/lib/python3.11/site-packages/gunicorn/util.py", line 640, in reraise
    raise value
  File "/home/runner/workspace/.pythonlibs/lib/python3.11/site-packages/gunicorn/workers/sync.py", line 184, in handle_request
    resp.close()
  File "/home/runner/workspace/.pythonlibs/lib/python3.11/site-packages/gunicorn/http/wsgi.py", line 399, in close
    self.send_headers()
  File "/home/runner/workspace/.pythonlibs/lib/python3.11/site-packages/gunicorn/http/wsgi.py", line 330, in send_headers
    util.write(self.sock, util.to_bytestring(header_str, "latin-1"))
  File "/home/runner/workspace/.pythonlibs/lib/python3.11/site-packages/gunicorn/util.py", line 298, in write
    sock.sendall(data)
OSError: [Errno 9] Bad file descriptor
[2025-08-07 03:23:11 +0000] [11484] [ERROR] Socket error processing request.
Traceback (most recent call last):
  File "/home/runner/workspace/.pythonlibs/lib/python3.11/site-packages/gunicorn/workers/sync.py", line 134, in handle
    self.handle_request(listener, req, client, addr)
  File "/home/runner/workspace/.pythonlibs/lib/python3.11/site-packages/gunicorn/workers/sync.py", line 192, in handle_request
    util.reraise(*sys.exc_info())
  File "/home/runner/workspace/.pythonlibs/lib/python3.11/site-packages/gunicorn/util.py", line 640, in reraise
    raise value
  File "/home/runner/workspace/.pythonlibs/lib/python3.11/site-packages/gunicorn/workers/sync.py", line 184, in handle_request
    resp.close()
  File "/home/runner/workspace/.pythonlibs/lib/python3.11/site-packages/gunicorn/http/wsgi.py", line 399, in close
    self.send_headers()
  File "/home/runner/workspace/.pythonlibs/lib/python3.11/site-packages/gunicorn/http/wsgi.py", line 330, in send_headers
    util.write(self.sock, util.to_bytestring(header_str, "latin-1"))
  File "/home/runner/workspace/.pythonlibs/lib/python3.11/site-packages/gunicorn/util.py", line 298, in write
    sock.sendall(data)
OSError: [Errno 9] Bad file descriptor